Workbook

Sheet Analysis-->

Sheet P&L Analysis
A1: FINE ORGANIC INDUSTRIES LIMITED
A2: Consolidated P&L A/c
N3: (INR Crores)
A4: Particulars | B4: =BS!B4 -> 2019-20 | C4: =BS!C4 -> 2020-21 | D4: =BS!D4 -> 2021-22 | E4: =BS!E4 -> 2022-23 | F4: =BS!F4 -> 2023-24 | G4: =BS!G4 -> 2024-25 | H4: 9ME Dec 25 | I4: 3ME Mar26 | J4: 2025-26 | K4: 2026-27 | L4: 2027-28 | M4: 2028-29 | N4: 2029-30
B5: Actuals | C5: Actuals | D5: Actuals | E5: Actuals | F5: Actuals | G5: Actuals | H5: Actuals | I5: Estimated | J5: Projected | K5: Projected | L5: Projected | M5: Projected | N5: Projected
A7: Revenue from Operations | B7: =103807.97/100 -> 1038.0797 | C7: =113321.84/100 -> 1133.2184 | D7: =187625.92/100 -> 1876.2592 | E7: =302307.66/100 -> 3023.0766 | F7: =212295.17/100 -> 2122.9517 | G7: =226914.79/100 -> 2269.1479 | H7: =174047.42/100 -> 1740.4742 | I7: =J7-H7 -> 621.14628 | J7: =Proj_PL!F30 -> 2361.6205 | K7: =Proj_PL!G30 -> 2539.6104 | L7: =Proj_PL!H30 -> 3403.8979 | M7: =Proj_PL!I30 -> 3887.0938 | N7: =Proj_PL!J30 -> 4254.9465
A8: YOY growth | C8: =C7/B7-1 -> 0.091648743 | D8: =D7/C7-1 -> 0.65569073 | E8: =E7/D7-1 -> 0.61122546 | F8: =F7/E7-1 -> -0.29775127 | G8: =G7/F7-1 -> 0.068864591 | J8: =J7/G7-1 -> 0.040752119 | K8: =K7/J7-1 -> 0.075367713 | L8: =L7/K7-1 -> 0.34032284 | M8: =M7/L7-1 -> 0.14195371 | N8: =N7/M7-1 -> 0.094634388
A10: Total Revenue (Net) | B10: =B7 -> 1038.0797 | C10: =C7 -> 1133.2184 | D10: =D7 -> 1876.2592 | E10: =E7 -> 3023.0766 | F10: =F7 -> 2122.9517 | G10: =G7 -> 2269.1479 | H10: =H7 -> 1740.4742 | I10: =I7 -> 621.14628 | ... N10: =N7 -> 4254.9465
A12: Cost of Materials Consumed (net) | B12: =63600.97/100+490.16 /100-3160.25/100 -> 609.3088 | C12: =71536.01/100+487.29 /100+578.37 /100 -> 726.0167 | D12: =121998.12/100+1038.56/100-4247.76/100 -> 1187.8892 | E12: =192292.15/100+8453.2/100-(22329.9)/100 -> 1784.1545 | F12: =108312.15/100+16.43/100+13374.82/100 -> 1217.034 | G12: =138152.07/100+370.98/100-(5667.43)/100 -> 1328.5562 | H12: =104683.77/100+593.42/100-946.63/100 -> 1043.3056 | I12: =J12-H12 -> 373.66669 | J12: =Proj_PL!F33 -> 1416.9723 | K12: =Proj_PL!G33 -> 1523.7663 | L12: =Proj_PL!H33 -> 2042.3387 | M12: =Proj_PL!I33 -> 2332.2563 | N12: =Proj_PL!J33 -> 2552.9679
A13: YOY growth | C13: =C12/B12-1 -> 0.19154146 | D13: =D12/C12-1 -> 0.63617338 | E13: =E12/D12-1 -> 0.50195363 | F13: =F12/E12-1 -> -0.31786513 | G13: =G12/F12-1 -> 0.091634416 | J13: =J12/G12-1 -> 0.066550508 | K13: =K12/J12-1 -> 0.075367713 | L13: =L12/K12-1 -> 0.34032284 | M13: =M12/L12-1 -> 0.14195371 | N13: =N12/M12-1 -> 0.094634388
A14: % to Revenue | B14: =B12/B$10 -> 0.58695763 | C14: =C12/C$10 -> 0.64066794 | D14: =D12/D$10 -> 0.63311572 | E14: =E12/E$10 -> 0.5901784 | F14: =F12/F$10 -> 0.57327446 | G14: =G12/G$10 -> 0.58548683 | H14: =H12/H$10 -> 0.59943756 | I14: =I12/I$10 -> 0.60157599 | ... N14: =N12/N$10 -> 0.6
A16: Employee Benefit Expense | B16: =7245.46/100 -> 72.4546 | C16: =7956.73/100 -> 79.5673 | D16: =8927.35/100 -> 89.2735 | E16: =10530.16/100 -> 105.3016 | F16: =11954.55/100 -> 119.5455 | G16: =13516.15/100 -> 135.1615 | H16: =12211.51/100 -> 122.1151 | I16: =J16-H16 -> 19.582129 | J16: =Proj_PL!F34 -> 141.69723 | K16: =Proj_PL!G34 -> 165.07468 | L16: =Proj_PL!H34 -> 221.25336 | M16: =Proj_PL!I34 -> 272.09657 | N16: =Proj_PL!J34 -> 297.84626
A17: YOY growth | C17: =C16/B16-1 -> 0.09816768 | D17: =D16/C16-1 -> 0.1219873 | E17: =E16/D16-1 -> 0.17953928 | F17: =F16/E16-1 -> 0.13526765 | G17: =G16/F16-1 -> 0.13062809 | J17: =J16/G16-1 -> 0.048354961 | K17: =K16/J16-1 -> 0.16498169 | L17: =L16/K16-1 -> 0.34032284 | M17: =M16/L16-1 -> 0.22979631 | N17: =N16/M16-1 -> 0.094634388
A18: % to Revenue | B18: =B16/B$10 -> 0.06979676 | C18: =C16/C$10 -> 0.070213562 | D18: =D16/D$10 -> 0.047580579 | E18: =E16/E$10 -> 0.034832594 | F18: =F16/F$10 -> 0.056310984 | G18: =G16/G$10 -> 0.05956487 | H18: =H16/H$10 -> 0.070161971 | I18: =I16/I$10 -> 0.031525793 | ... N18: =N16/N$10 -> 0.07
A20: Other Expenses | B20: =11584.36/100 -> 115.8436 | C20: =12837.96/100 -> 128.3796 | D20: =23458.95/100 -> 234.5895 | E20: =30254.3/100 -> 302.543 | F20: =25189.08/100 -> 251.8908 | G20: =29255.29/100 -> 292.5529 | H20: =22193.99/100 -> 221.9399 | I20: =J20-H20 -> 64.935339 | J20: =Proj_PL!F35 -> 286.87524 | K20: =Proj_PL!G35 -> 308.49637 | L20: =Proj_PL!H35 -> 413.48473 | M20: =Proj_PL!I35 -> 472.18042 | N20: =Proj_PL!J35 -> 516.86493
A21: YOY growth | C21: =C20/B20-1 -> 0.10821487 | D21: =D20/C20-1 -> 0.82731135 | E21: =E20/D20-1 -> 0.28966983 | F21: =F20/E20-1 -> -0.16742149 | G21: =G20/F20-1 -> 0.16142749 | J21: =J20/G20-1 -> -0.019407298 | K21: =K20/J20-1 -> 0.075367713 | L21: =L20/K20-1 -> 0.34032284 | M21: =M20/L20-1 -> 0.14195371 | N21: =N20/M20-1 -> 0.094634388
A22: % to Revenue | B22: =B20/B$10 -> 0.11159413 | C22: =C20/C$10 -> 0.11328761 | D22: =D20/D$10 -> 0.12503043 | E22: =E20/E$10 -> 0.10007785 | F22: =F20/F$10 -> 0.11865122 | G22: =G20/G$10 -> 0.12892633 | H22: =H20/H$10 -> 0.12751691 | I22: =I20/I$10 -> 0.10454114 | ... N22: =N20/N$10 -> 0.1214739
A23: Total Expenditure | B23: =B12+B16+B20 -> 797.607 | C23: =C12+C16+C20 -> 933.9636 | D23: =D12+D16+D20 -> 1511.7522 | E23: =E12+E16+E20 -> 2191.9991 | F23: =F12+F16+F20 -> 1588.4703 | G23: =G12+G16+G20 -> 1756.2706 | H23: =H12+H16+H20 -> 1387.3606 | I23: =I12+I16+I20 -> 458.18416 | ... N23: =N12+N16+N20 -> 3367.6791
A24: EBITDA | B24: =B10-B23 -> 240.4727 | C24: =C10-C23 -> 199.2548 | D24: =D10-D23 -> 364.507 | E24: =E10-E23 -> 831.0775 | F24: =F10-F23 -> 534.4814 | G24: =G10-G23 -> 512.8773 | H24: =H10-H23 -> 353.1136 | I24: =I10-I23 -> 162.96213 | ... N24: =N10-N23 -> 887.26743
A25: EBITDA Margins | B25: =B24/B$10 -> 0.23165148 | C25: =C24/C$10 -> 0.17583089 | D25: =D24/D$10 -> 0.19427326 | E25: =E24/E$10 -> 0.27491116 | F25: =F24/F$10 -> 0.25176333 | G25: =G24/G$10 -> 0.22602198 | H25: =H24/H$10 -> 0.20288356 | I25: =I24/I$10 -> 0.26235708 | ... N25: =N24/N$10 -> 0.2085261
A26: Other Income | B26: =2018.59/100 -> 20.1859 | C26: =1709.77/100 -> 17.0977 | D26: =3289.38/100 -> 32.8938 | E26: =6415.18/100 -> 64.1518 | F26: =7187.64/100 -> 71.8764 | G26: =9760/100 -> 97.6 | H26: =8207.66/100 -> 82.0766 | I26: =J26-H26 -> -9.5107 | J26: =Proj_PL!F39 -> 72.5659 | K26: =Proj_PL!G39 -> 72.5659 | L26: =Proj_PL!H39 -> 72.5659 | M26: =Proj_PL!I39 -> 72.5659 | N26: =Proj_PL!J39 -> 72.5659
A27: YOY growth | C27: =C26/B26-1 -> -0.15298798 | D27: =D26/C26-1 -> 0.9238728 | E27: =E26/D26-1 -> 0.95027026 | F27: =F26/E26-1 -> 0.12041127 | G27: =G26/F26-1 -> 0.35788659 | J27: =J26/G26-1 -> -0.25649693 | K27: =K26/J26-1 -> 0 | L27: =L26/K26-1 -> 0 | M27: =M26/L26-1 -> 0 | N27: =N26/M26-1 -> 0
A28: Interest | B28: =482.11 /100 -> 4.8211 | C28: =612.98 /100 -> 6.1298 | D28: =494.15/100 -> 4.9415 | E28: =456.78/100 -> 4.5678 | F28: =243.3/100 -> 2.433 | G28: =219.56/100 -> 2.1956 | H28: =141.39/100 -> 1.4139 | J28: =Proj_PL!F40 -> 0 | K28: =Proj_PL!G40 -> 0 | L28: =Proj_PL!H40 -> 0 | M28: =Proj_PL!I40 -> 0 | N28: =Proj_PL!J40 -> 0
A29: Depreciation | B29: =3465.53/100 -> 34.6553 | C29: =4676.91/100 -> 46.7691 | D29: =3990.28/100 -> 39.9028 | E29: =4789.3/100 -> 47.893 | F29: =5660.07/100 -> 56.6007 | G29: =5229.62/100 -> 52.2962 | H29: =3836.98/100 -> 38.3698 | J29: =Proj_PL!F41 -> 67.35736 | K29: =Proj_PL!G41 -> 90.362868 | L29: =Proj_PL!H41 -> 108.23765 | M29: =Proj_PL!I41 -> 115.85098 | N29: =Proj_PL!J41 -> 118.4991
A30: Exceptional item | B30: =-(506.03)/100 -> -5.0603 | C30: =-(130.45)/100 -> -1.3045 | D30: =-(102.88)/100 -> -1.0288 | E30: =-(177.43)/100 -> -1.7743 | F30: =-263.94/100-56.32/100 -> -3.2026 | G30: =-82.85/100 -> -0.8285 | J30: =Proj_PL!#REF! -> #REF! | K30: =Proj_PL!#REF! -> #REF! | L30: =Proj_PL!#REF! -> #REF! | M30: =Proj_PL!#REF! -> #REF! | N30: =Proj_PL!#REF! -> #REF! | O30: share from JV
A31: PBT | B31: =B24-B28-B29+B26+B30 -> 216.1219 | C31: =C24-C28-C29+C26+C30 -> 162.1491 | D31: =D24-D28-D29+D26+D30 -> 351.5277 | E31: =E24-E28-E29+E26+E30 -> 840.9942 | F31: =F24-F28-F29+F26+F30 -> 544.1215 | G31: =G24-G28-G29+G26+G30 -> 555.157 | H31: =H24-H28-H29+H26+H30 -> 395.4065
A32: PBT Margins | B32: =B31/B$10 -> 0.20819394 | C32: =C31/C$10 -> 0.14308725 | D32: =D31/D$10 -> 0.18735562 | E32: =E31/E$10 -> 0.2781915 | F32: =F31/F$10 -> 0.25630423 | G32: =G31/G$10 -> 0.24465439 | H32: =H31/H$10 -> 0.2271832
B33: =21612.19/100 -> 216.1219 | C33: =16214.91/100 -> 162.1491 | D33: =35152.77/100 -> 351.5277 | E33: =84099.42/100 -> 840.9942 | F33: =54412.15/100 -> 544.1215 | G33: =55515.7/100 -> 555.157 | H33: =39540.65/100 -> 395.4065
B34: =B31-B33 -> 0 | C34: =C31-C33 -> 0 | D34: =D31-D33 -> 0 | E34: =E31-E33 -> 0 | F34: =F31-F33 -> 0 | G34: =G31-G33 -> 0 | H34: =H31-H33 -> 0

Sheet Other Expenses
A1: ='P&L Analysis'!A1 -> FINE ORGANIC INDUSTRIES LIMITED
G2: ='P&L Analysis'!N3 -> (INR Crores)
A3: ='P&L Analysis'!A4 -> Particulars | B3: ='P&L Analysis'!B4 -> 2019-20 | C3: ='P&L Analysis'!C4 -> 2020-21 | D3: ='P&L Analysis'!D4 -> 2021-22 | E3: ='P&L Analysis'!E4 -> 2022-23 | F3: ='P&L Analysis'!F4 -> 2023-24 | G3: ='P&L Analysis'!G4 -> 2024-25
A5: Revenue | B5: ='P&L Analysis'!B10 -> 1038.0797 | C5: ='P&L Analysis'!C10 -> 1133.2184 | D5: ='P&L Analysis'!D10 -> 1876.2592 | E5: ='P&L Analysis'!E10 -> 3023.0766 | F5: ='P&L Analysis'!F10 -> 2122.9517 | G5: ='P&L Analysis'!G10 -> 2269.1479
C6: =C5/B5-1 -> 0.091648743 | D6: =D5/C5-1 -> 0.65569073 | E6: =E5/D5-1 -> 0.61122546 | F6: =F5/E5-1 -> -0.29775127 | G6: =G5/F5-1 -> 0.068864591
A7: Other Expenses
A8: Advertisement and publicity | D8: =19.45/(100) -> 0.1945 | E8: =33.12/(100) -> 0.3312 | F8: =196.98/(100) -> 1.9698 | G8: =182.54/(100) -> 1.8254
A9: YOY growth | E9: =E8/D8-1 -> 0.70282776 | F9: =F8/E8-1 -> 4.9474638 | G9: =G8/F8-1 -> -0.073306935
A10: % to Revenue | B10: =B8/B$5 -> 0 | C10: =C8/C$5 -> 0 | D10: =D8/D$5 -> 0.00010366372 | E10: =E8/E$5 -> 0.00010955726 | F10: =F8/F$5 -> 0.00092785907 | G10: =G8/G$5 -> 0.00080444294
A12: Auditor's remuneration (incl. Cost) | D12: =(27.75+9.5+9.75+1+2.5)/(100) -> 0.505 | E12: =(31+11+10.5+9.2+3)/(100) -> 0.647 | F12: =(33.5+11.5+12+7.82+3.5)/(100) -> 0.6832 | G12: =(102.74+19.4+12.75+4+3.5)/(100) -> 1.4239
A13: YOY growth | E13: =E12/D12-1 -> 0.28118812 | F13: =F12/E12-1 -> 0.055950541 | G13: =G12/F12-1 -> 1.0841628
A14: % to Revenue | B14: =B12/B$5 -> 0 | C14: =C12/C$5 -> 0 | D14: =D12/D$5 -> 0.00026915258 | E14: =E12/E$5 -> 0.00021402038 | F14: =F12/F$5 -> 0.00032181608 | G14: =G12/G$5 -> 0.00062750427
A16: Consumption of stores and spares | D16: =37.22/(100) -> 0.3722 | E16: =40.87/(100) -> 0.4087 | F16: =79.64/(100) -> 0.7964 | G16: =72.46/(100) -> 0.7246
A17: YOY growth | E17: =E16/D16-1 -> 0.098065556 | F17: =F16/E16-1 -> 0.94861757 | G17: =G16/F16-1 -> -0.090155701
A18: % to Revenue | B18: =B16/B$5 -> 0 | C18: =C16/C$5 -> 0 | D18: =D16/D$5 -> 0.00019837344 | E18: =E16/E$5 -> 0.0001351934 | F18: =F16/F$5 -> 0.00037513807 | G18: =G16/G$5 -> 0.00031932692
A20: CSR | D20: =397.88/(100) -> 3.9788 | E20: =478.05/(100) -> 4.7805 | F20: =837.21/(100) -> 8.3721 | G20: =1080.8/(100) -> 10.808
A21: YOY growth | E21: =E20/D20-1 -> 0.20149291 | F21: =F20/E20-1 -> 0.75130217 | G21: =G20/F20-1 -> 0.29095448
A22: % to Revenue | B22: =B20/B$5 -> 0 | C22: =C20/C$5 -> 0 | D22: =D20/D$5 -> 0.0021206025 | E22: =E20/E$5 -> 0.001581336 | F22: =F20/F$5 -> 0.003943613 | G22: =G20/G$5 -> 0.0047630214
A24: Corporate environment responsibility | D24: =14.76/(100) -> 0.1476 | E24: =37.71/(100) -> 0.3771 | F24: =25.4/(100) -> 0.254 | G24: =0/(100) -> 0
A25: YOY growth | E25: =E24/D24-1 -> 1.554878 | F25: =F24/E24-1 -> -0.32643861 | G25: =G24/F24-1 -> -1
A26: % to Revenue | B26: =B24/B$5 -> 0 | C26: =C24/C$5 -> 0 | D26: =D24/D$5 -> 7.8667169e-05 | E26: =E24/E$5 -> 0.00012474047 | F26: =F24/F$5 -> 0.00011964474 | G26: =G24/G$5 -> 0
A28: Director sitting fees | D28: =22.65/(100) -> 0.2265 | E28: =33.8/(100) -> 0.338 | F28: =35.15/(100) -> 0.3515 | G28: =31.6/(100) -> 0.316
A29: YOY growth | E29: =E28/D28-1 -> 0.49227373 | F29: =F28/E28-1 -> 0.039940828 | G29: =G28/F28-1 -> -0.10099573
A30: % to Revenue | B30: =B28/B$5 -> 0 | C30: =C28/C$5 -> 0 | D30: =D28/D$5 -> 0.00012071893 | E30: =E28/E$5 -> 0.00011180663 | F30: =F28/F$5 -> 0.00016557136 | G30: =G28/G$5 -> 0.00013925932
A32: Electricity charges | D32: =61.27/(100) -> 0.6127 | E32: =71.39/(100) -> 0.7139 | F32: =67.93/(100) -> 0.6793 | G32: =99.87/(100) -> 0.9987
A33: YOY growth | E33: =E32/D32-1 -> 0.16517056 | F33: =F32/E32-1 -> -0.048466172 | G33: =G32/F32-1 -> 0.4701899
A34: % to Revenue | B34: =B32/B$5 -> 0 | C34: =C32/C$5 -> 0 | D34: =D32/D$5 -> 0.00032655403 | E34: =E32/E$5 -> 0.00023615015 | F34: =F32/F$5 -> 0.00031997902 | G34: =G32/G$5 -> 0.00044012116
A36: Expected credit loss provisions | D36: =0/(100) -> 0 | E36: =110.05/(100) -> 1.1005 | F36: =76.98/(100) -> 0.7698 | G36: =60.58/(100) -> 0.6058
A37: YOY growth | E37: =IFERROR(E36/D36-1,0) -> 0 | F37: =F36/E36-1 -> -0.30049977 | G37: =G36/F36-1 -> -0.21304235
A38: % to Revenue | B38: =B36/B$5 -> 0 | C38: =C36/C$5 -> 0 | D38: =D36/D$5 -> 0 | E38: =E36/E$5 -> 0.00036403312 | F38: =F36/F$5 -> 0.00036260834 | G38: =G36/G$5 -> 0.00026697246
A40: Freight and forwarding | D40: =9969.35/(100) -> 99.6935 | E40: =10362.44/(100) -> 103.6244 | F40: =4315.84/(100) -> 43.1584 | G40: =6857.71/(100) -> 68.5771
A41: YOY growth | E41: =E40/D40-1 -> 0.039429852 | F41: =F40/E40-1 -> -0.58351122 | G41: =G40/F40-1 -> 0.58896298
A42: % to Revenue | B42: =B40/B$5 -> 0 | C42: =C40/C$5 -> 0 | D42: =D40/D$5 -> 0.053134183 | E42: =E40/E$5 -> 0.034277795 | F42: =F40/F$5 -> 0.020329431 | G42: =G40/G$5 -> 0.030221521
A44: Insurance | D44: =335.95/(100) -> 3.3595 | E44: =577.14/(100) -> 5.7714 | F44: =571.77/(100) -> 5.7177 | G44: =632.34/(100) -> 6.3234
A45: YOY growth | E45: =E44/D44-1 -> 0.71793422 | F45: =F44/E44-1 -> -0.0093045015 | G45: =G44/F44-1 -> 0.1059342
A46: % to Revenue | B46: =B44/B$5 -> 0 | C46: =C44/C$5 -> 0 | D46: =D44/D$5 -> 0.0017905309 | E46: =E44/E$5 -> 0.0019091147 | F46: =F44/F$5 -> 0.0026932784 | G46: =G44/G$5 -> 0.0027866848
A48: Laboratory | D48: =92.73/(100) -> 0.9273 | E48: =136.15/(100) -> 1.3615 | F48: =167.41/(100) -> 1.6741 | G48: =171.88/(100) -> 1.7188
A49: YOY growth | E49: =E48/D48-1 -> 0.46824113 | F49: =F48/E48-1 -> 0.22959971 | G49: =G48/F48-1 -> 0.026700914
A50: % to Revenue | B50: =B48/B$5 -> 0 | C50: =C48/C$5 -> 0 | D50: =D48/D$5 -> 0.00049422809 | E50: =E48/E$5 -> 0.000450369 | F50: =F48/F$5 -> 0.00078857187 | G50: =G48/G$5 -> 0.00075746495
A52: Legal and professional | D52: =548.38/(100) -> 5.4838 | E52: =825.38/(100) -> 8.2538 | F52: =2287.84/(100) -> 22.8784 | G52: =1145.46/(100) -> 11.4546
...

Sheet BS
A1: ='P&L Analysis'!A1 -> FINE ORGANIC INDUSTRIES LIMITED
A2: BALANCE SHEET
G3: (INR Crores)
A4: Particulars | B4: 2019-20 | C4: 2020-21 | D4: 2021-22 | E4: 2022-23 | F4: 2023-24 | G4: 2024-25 | H4: 6ME Sep 25
A5: ASSETS
A6: Non-Current Assets
A7: Property, plant and equipment | B7: =21591.69/100 -> 215.9169 | C7: =19531.15/100 -> 195.3115 | D7: =22873.45/100 -> 228.7345 | E7: =21123.94/100 -> 211.2394 | F7: =26249.43/100 -> 262.4943 | G7: =35831.38/100 -> 358.3138 | H7: =36408.67/100 -> 364.0867
A8: Capital work in progress | B8: =584.11 /100 -> 5.8411 | C8: =2630.42/100 -> 26.3042 | D8: =1412.47/100 -> 14.1247 | E8: =4044.08/100 -> 40.4408 | F8: =2972.98/100 -> 29.7298 | G8: =2717.34/100 -> 27.1734 | H8: =3552.89/100 -> 35.5289
A9: Intangible assets | B9: =85.74 /100 -> 0.8574 | C9: =54.18 /100 -> 0.5418 | D9: =57.11/100 -> 0.5711 | E9: =148.54/100 -> 1.4854 | F9: =169.55/100 -> 1.6955 | G9: =255.38/100 -> 2.5538 | H9: =212.64/100 -> 2.1264
A10: ROU assets | D10: 0 | E10: =130.87/100 -> 1.3087 | F10: =407.09/100 -> 4.0709 | G10: =255.55/100 -> 2.5555 | H10: =680.24/100 -> 6.8024
A11: Financial assets
A12: Investments | B12: =3279.76/100 -> 32.7976 | C12: =3109.91/100 -> 31.0991 | D12: =3061.06/100 -> 30.6106 | E12: =3879.83/100 -> 38.7983 | F12: =3616.08/100 -> 36.1608 | G12: =3527.15/100 -> 35.2715 | H12: =3351.28/100 -> 33.5128
A13: Loans | B13: =99.88 /100 -> 0.9988 | C13: =123.49/100 -> 1.2349 | D13: =85.29/100 -> 0.8529 | E13: =90.86/100 -> 0.9086 | F13: =121.28/100 -> 1.2128 | G13: =89.97/100 -> 0.8997 | H13: =80.96/100 -> 0.8096
A14: Other non-current financial assets | B14: =301.18 /100 -> 3.0118 | C14: =255.72 /100 -> 2.5572 | D14: =373.27/100 -> 3.7327 | E14: =757.29/100 -> 7.5729 | F14: =1239.41/100 -> 12.3941 | G14: =21902.08/100 -> 219.0208 | H14: =14137.74/100 -> 141.3774 | I14: FD with banks
A15: Deferred tax assets | B15: =671.81/100 -> 6.7181 | C15: =794.9 /100 -> 7.949 | D15: =835.57/100 -> 8.3557 | E15: =1068.74/100 -> 10.6874 | F15: =1327.92/100 -> 13.2792 | G15: =1530.35/100 -> 15.3035 | H15: =1683.35/100 -> 16.8335
A16: Other non-current assets | B16: =6165.23/100 -> 61.6523 | C16: =6214.71/100 -> 62.1471 | D16: =6099.12/100 -> 60.9912 | E16: =7436.46/100 -> 74.3646 | F16: =6494.29/100 -> 64.9429 | G16: =3621.7/100 -> 36.217 | H16: =3944.43/100 -> 39.4443 | I16: includes capital advances --> | J16: =2730.23/100 -> 27.3023 | K16: =2690.15/100 -> 26.9015 | L16: =2614.45/100 -> 26.1445 | M16: =2841.33/100 -> 28.4133 | N16: =5068.09/100 -> 50.6809 | O16: =2896.62/100 -> 28.9662
A17: Total Non-Current Assets | B17: =SUM(B7:B16) -> 327.794 | C17: =SUM(C7:C16) -> 327.1448 | D17: =SUM(D7:D16) -> 347.9734 | E17: =SUM(E7:E16) -> 386.8061 | F17: =SUM(F7:F16) -> 425.9803 | G17: =SUM(G7:G16) -> 697.309 | H17: =SUM(H7:H16) -> 640.522 | J17: =J16/B16 -> 0.44284317 | K17: =K16/C16 -> 0.43286815 | L17: =L16/D16 -> 0.4286602 | M17: =M16/E16 -> 0.38208099 | N17: =N16/F16 -> 0.7803917 | O17: =O16/G16 -> 0.79979568
A18: Current Assets
A19: Inventories | B19: =13167.15/100 -> 131.6715 | C19: =12617.94/100 -> 126.1794 | D19: =23558.55/100 -> 235.5855 | E19: =44497.55/100 -> 444.9755 | F19: =26089.22/100 -> 260.8922 | G19: =36291.5/100 -> 362.915 | H19: =39939.96/100 -> 399.3996
A20: Financial assets
A21: Trade receivables | B21: =13233.32/100 -> 132.3332 | C21: =16162.86/100 -> 161.6286 | D21: =30136.59/100 -> 301.3659 | E21: =35064.61/100 -> 350.6461 | F21: =31131.21/100 -> 311.3121 | G21: =33153.47/100 -> 331.5347 | H21: =27293.74/100 -> 272.9374
A22: Cash and cash equivalents | B22: =20566.37/100 -> 205.6637 | C22: =25897.28/100 -> 258.9728 | D22: =22566.44/100 -> 225.6644 | E22: =51482.26/100 -> 514.8226 | F22: =69505.34/100 -> 695.0534 | G22: =18915.46/100 -> 189.1546 | H22: =21438.78/100 -> 214.3878
A23: Bank balances other than above | B23: =475.14/100 -> 4.7514 | C23: =477.01 /100 -> 4.7701 | D23: =689.39/100 -> 6.8939 | E23: =815.43/100 -> 8.1543 | F23: =35346.11/100 -> 353.4611 | G23: =76079.42/100 -> 760.7942 | H23: =94876.7/100 -> 948.767
A24: Loans | D24: =46.3/100 -> 0.463 | E24: =107.91/100 -> 1.0791 | F24: =65.29/100 -> 0.6529 | G24: =62.87/100 -> 0.6287 | H24: =55.82/100 -> 0.5582
A25: Other current financial assets | B25: =32.8 /100 -> 0.328 | C25: =23.96 /100 -> 0.2396 | D25: =24.14/100 -> 0.2414 | E25: =277.54/100 -> 2.7754 | F25: =73.73/100 -> 0.7373 | G25: =154.04/100 -> 1.5404 | H25: =233/100 -> 2.33
A26: Current tax assets | B26: =702.1 /100 -> 7.021 | C26: =526.99 /100 -> 5.2699 | D26: =654.47/100 -> 6.5447 | E26: =1817.08/100 -> 18.1708 | F26: =1897.81/100 -> 18.9781 | G26: =1970.37/100 -> 19.7037 | H26: =1065.29/100 -> 10.6529
A27: Other current assets | B27: =4249.36/100 -> 42.4936 | C27: =6341.35/100 -> 63.4135 | D27: =11161.91/100 -> 111.6191 | E27: =7917.37/100 -> 79.1737 | F27: =4070.09/100 -> 40.7009 | G27: =14709.35/100 -> 147.0935 | H27: =17083.74/100 -> 170.8374
A28: Total Current Assets | B28: =SUM(B19:B27) -> 524.2624 | C28: =SUM(C19:C27) -> 620.4739 | D28: =SUM(D19:D27) -> 888.3779 | E28: =SUM(E19:E27) -> 1419.7975 | F28: =SUM(F19:F27) -> 1681.788 | G28: =SUM(G19:G27) -> 1813.3648 | H28: =SUM(H19:H27) -> 2019.8703
A29: Total Assets | B29: =B28+B17 -> 852.0564 | C29: =C28+C17 -> 947.6187 | D29: =D28+D17 -> 1236.3513 | E29: =E28+E17 -> 1806.6036 | F29: =F28+F17 -> 2107.7683 | G29: =G28+G17 -> 2510.6738 | H29: =H28+H17 -> 2660.3923
A30: EQUITY AND LIABILITIES
A31: Equity share capital | B31: =1533/100 -> 15.33 | C31: =1533/100 -> 15.33 | D31: =1533/100 -> 15.33 | E31: =1533/100 -> 15.33 | F31: =1533/100 -> 15.33 | G31: =1533/100 -> 15.33 | H31: =1533/100 -> 15.33
A32: Other equity | B32: =60356.07/100 -> 603.5607 | C32: =71605.67/100 -> 716.0567 | D32: =94387.19/100 -> 943.8719 | E32: =152591.89/100 -> 1525.9189 | F32: =190571.91/100 -> 1905.7191 | G32: =227990.04/100 -> 2279.9004 | H32: =246189.57/100 -> 2461.8957
A33: NCI | B33: =5.08 /100 -> 0.0508 | C33: =6.91/100 -> 0.0691
A34: Total Equity | B34: =SUM(B31:B33) -> 618.9415 | C34: =SUM(C31:C33) -> 731.4558 | D34: =SUM(D31:D33) -> 959.2019 | E34: =SUM(E31:E33) -> 1541.2489 | F34: =SUM(F31:F33) -> 1921.0491 | G34: =SUM(G31:G33) -> 2295.2304 | H34: =SUM(H31:H33) -> 2477.2257
A35: Non-Current Liabilities
A36: Borrowings | B36: =9146.08/100 -> 91.4608 | C36: =5674.43/100 -> 56.7443 | D36: =2508.32/100 -> 25.0832 | E36: 0 | F36: 0 | G36: 0 | H36: =924.24/100 -> 9.2424
A37: Lease liability | B37: 0 | C37: 0 | D37: 0 | E37: =81.57/100 -> 0.8157 | F37: =246.96/100 -> 2.4696 | G37: =102.12/100 -> 1.0212 | H37: =374.22/100 -> 3.7422
A38: Others | B38: =755.86 /100 -> 7.5586 | C38: =435.3 /100 -> 4.353 | D38: =86.61/100 -> 0.8661 | E38: 0 | F38: 0 | G38: 0 | H38: 0
A39: Total Non-Current Liabilities | B39: =SUM(B36:B38) -> 99.0194 | C39: =SUM(C36:C38) -> 61.0973 | D39: =SUM(D36:D38) -> 25.9493 | E39: =SUM(E36:E38) -> 0.8157 | F39: =SUM(F36:F38) -> 2.4696 | G39: =SUM(G36:G38) -> 1.0212 | H39: =SUM(H36:H38) -> 12.9846
A40: Current Liabilities
...

Sheet WC
A1: ='P&L Analysis'!A1 -> FINE ORGANIC INDUSTRIES LIMITED
A3: EXHIBIT A: CALCULATION OF WORKING CAPITAL | H3: (INR crores)
A4: Particulars | B4: =BS!B4 -> 2019-20 | C4: =BS!C4 -> 2020-21 | D4: =BS!D4 -> 2021-22 | E4: =BS!E4 -> 2022-23 | F4: =BS!F4 -> 2023-24 | G4: =BS!G4 -> 2024-25 | H4: 45930
A5: Current assets, loans & advances
A6: Inventories | B6: =BS!B19 -> 131.6715 | C6: =BS!C19 -> 126.1794 | D6: =BS!D19 -> 235.5855 | E6: =BS!E19 -> 444.9755 | F6: =BS!F19 -> 260.8922 | G6: =BS!G19 -> 362.915 | H6: =BS!H19 -> 399.3996
A7: Trade receivables | B7: =BS!B21 -> 132.3332 | C7: =BS!C21 -> 161.6286 | D7: =BS!D21 -> 301.3659 | E7: =BS!E21 -> 350.6461 | F7: =BS!F21 -> 311.3121 | G7: =BS!G21 -> 331.5347 | H7: =BS!H21 -> 272.9374
A8: Other current assets | B8: =BS!B27 -> 42.4936 | C8: =BS!C27 -> 63.4135 | D8: =BS!D27 -> 111.6191 | E8: =BS!E27 -> 79.1737 | F8: =BS!F27 -> 40.7009 | G8: =BS!G27 -> 147.0935 | H8: =BS!H27 -> 170.8374 | I8: prepaid expenses, balances with govt, gratuity fund, advances to others and suppliers
A9: Other non-current assets | B9: =BS!B16-BS!J16 -> 34.35 | C9: =BS!C16-BS!K16 -> 35.2456 | D9: =BS!D16-BS!L16 -> 34.8467 | E9: =BS!E16-BS!M16 -> 45.9513 | F9: =BS!F16-BS!N16 -> 14.262 | G9: =BS!G16-BS!O16 -> 7.2508 | H9: =BS!H16-BS!P16 -> 39.4443 | I9: excluding capital advances
A10: Other current financial assets | B10: =BS!B25 -> 0.328 | C10: =BS!C25 -> 0.2396 | D10: =BS!D25 -> 0.2414 | E10: =BS!E25 -> 2.7754 | F10: =BS!F25 -> 0.7373 | G10: =BS!G25 -> 1.5404 | H10: =BS!H25 -> 2.33
A11: Other non-current financial assets | B11: =BS!B14*0 -> 0 | C11: =BS!C14*0 -> 0 | D11: =BS!D14*0 -> 0 | E11: =BS!E14*0 -> 0 | F11: =BS!F14*0 -> 0 | G11: =BS!G14*0 -> 0 | H11: =BS!H14*0 -> 0 | I11: FD with banks
A12: Other current tax assets | B12: =BS!B26 -> 7.021 | C12: =BS!C26 -> 5.2699 | D12: =BS!D26 -> 6.5447 | E12: =BS!E26 -> 18.1708 | F12: =BS!F26 -> 18.9781 | G12: =BS!G26 -> 19.7037 | H12: =BS!H26 -> 10.6529
A13: Short term loans and advances | B13: =BS!B24 -> 0 | C13: =BS!C24 -> 0 | D13: =BS!D24 -> 0.463 | E13: =BS!E24 -> 1.0791 | F13: =BS!F24 -> 0.6529 | G13: =BS!G24 -> 0.6287 | H13: =BS!H24 -> 0.5582
A14: Long term loans and advances | B14: =BS!B13 -> 0.9988 | C14: =BS!C13 -> 1.2349 | D14: =BS!D13 -> 0.8529 | E14: =BS!E13 -> 0.9086 | F14: =BS!F13 -> 1.2128 | G14: =BS!G13 -> 0.8997 | H14: =BS!H13 -> 0.8096
A15: (A) | B15: =SUM(B6:B14) -> 349.1961 | C15: =SUM(C6:C14) -> 393.2115 | D15: =SUM(D6:D14) -> 691.5192 | E15: =SUM(E6:E14) -> 943.6805 | F15: =SUM(F6:F14) -> 648.7483 | G15: =SUM(G6:G14) -> 871.5665 | H15: =SUM(H6:H14) -> 896.9694
A16: Less: Current liabilities & provisions
A17: Trade payables | B17: =BS!B43 -> 85.7508 | C17: =BS!C43 -> 97.7813 | D17: =BS!D43 -> 153.5543 | E17: =BS!E43 -> 175.8318 | F17: =BS!F43 -> 135.4094 | G17: =BS!G43 -> 155.4527 | H17: =BS!H43 -> 108.4939
A18: Other current liabilities | B18: =BS!B45 -> 5.6088 | C18: =BS!C45 -> 4.3197 | D18: =BS!D45 -> 15.9512 | E18: =BS!E45 -> 14.4807 | F18: =BS!F45 -> 9.4272 | G18: =BS!G45 -> 11.024 | H18: =BS!H45 -> 15.0547
A19: Other non-current liabilities | B19: =BS!B38 -> 7.5586 | C19: =BS!C38 -> 4.353 | D19: =BS!D38 -> 0.8661 | E19: =BS!E38 -> 0 | F19: =BS!F38 -> 0 | G19: =BS!G38 -> 0 | H19: =BS!H38 -> 0
A20: Other current financial liabilities | B20: =BS!B44-BS!J44 -> 1.6313 | C20: =BS!C44 -> 2.5161 | D20: =BS!D44 -> 1.4717 | E20: =BS!E44 -> 3.2086 | F20: =BS!F44 -> 2.64 | G20: =BS!G44 -> 2.3104 | H20: =BS!H44 -> 2.2601
A21: Other non-current financial liabilities | B21: 0 | C21: 0 | D21: 0 | E21: 0 | F21: 0 | G21: 0 | H21: 0
A22: Other current tax liabilities | B22: =BS!B47 -> 4.5711 | C22: =BS!C47 -> 4.5711 | D22: =BS!D47 -> 16.4711 | E22: =BS!E47 -> 23.8254 | F22: =BS!F47 -> 14.9919 | G22: =BS!G47 -> 14.1713 | H22: =BS!H47 -> 5.3245
A23: Short-term provisions | B23: =BS!B46 -> 3.275 | C23: =BS!C46 -> 13.4489 | D23: =BS!D46 -> 30.3075 | E23: =BS!E46 -> 19.4834 | F23: =BS!F46 -> 20.0189 | G23: =BS!G46 -> 29.6897 | H23: =BS!H46 -> 35.664
A24: Long-term provisions | B24: 0 | C24: 0 | D24: 0 | E24: 0 | F24: 0 | G24: 0 | H24: 0
A25: (B) | B25: =SUM(B17:B24) -> 108.3956 | C25: =SUM(C17:C24) -> 126.9901 | D25: =SUM(D17:D24) -> 218.6219 | E25: =SUM(E17:E24) -> 236.8299 | F25: =SUM(F17:F24) -> 182.4874 | G25: =SUM(G17:G24) -> 212.6481 | H25: =SUM(H17:H24) -> 166.7972
A26: Net working capital (A-B) | B26: =B15-B25 -> 240.8005 | C26: =C15-C25 -> 266.2214 | D26: =D15-D25 -> 472.8973 | E26: =E15-E25 -> 706.8506 | F26: =F15-F25 -> 466.2609 | G26: =G15-G25 -> 658.9184 | H26: =H15-H25 -> 730.1722
A28: Incremental working capital | C28: =C26-B26 -> 25.4209 | D28: =D26-C26 -> 206.6759 | E28: =E26-D26 -> 233.9533 | F28: =F26-E26 -> -240.5897 | G28: =G26-F26 -> 192.6575 | H28: =H26-G26 -> 71.2538
A29: Net Sales | B29: ='P&L Analysis'!B10 -> 1038.0797 | C29: ='P&L Analysis'!C10 -> 1133.2184 | D29: ='P&L Analysis'!D10 -> 1876.2592 | E29: ='P&L Analysis'!E10 -> 3023.0766 | F29: ='P&L Analysis'!F10 -> 2122.9517 | G29: ='P&L Analysis'!G10 -> 2269.1479 | H29: ='P&L Analysis'!H10*2 -> 3480.9484
A30: % to Sales | B30: =B26/B29 -> 0.23196726 | C30: =C26/C29 -> 0.23492506 | D30: =D26/D29 -> 0.25204263 | E30: =E26/E29 -> 0.23381829 | F30: =F26/F29 -> 0.2196286 | G30: =G26/G29 -> 0.29038142 | H30: =H26/H29 -> 0.20976243
A32: Working capital days | B32: =B26/B29*365 -> 84.668049 | C32: =C26/C29*365 -> 85.747647 | D32: =D26/D29*365 -> 91.995559 | E32: =E26/E29*365 -> 85.343676 | F32: =F26/F29*365 -> 80.164437 | G32: =G26/G29*365 -> 105.98922 | H32: =H26/H29*365 -> 76.563287

Sheet Ratios
A1: =BS!A1 -> FINE ORGANIC INDUSTRIES LIMITED
A3: Inventory T/o. Ratio
G4: (no of days) | P4: (Days)
A5: Particulars | B5: =BS!B4 -> 2019-20 | C5: =BS!C4 -> 2020-21 | D5: =BS!D4 -> 2021-22 | E5: =BS!E4 -> 2022-23 | F5: =BS!F4 -> 2023-24 | G5: =BS!G4 -> 2024-25 | N5: Year | O5: Fixed assets T/o ratio | P5: Inventory T/o ratio | Q5: Debtor T/o ratio | R5: Creditor T/o ratio
A6: Inventory | B6: =BS!B19 -> 131.6715 | C6: =BS!C19 -> 126.1794 | D6: =BS!D19 -> 235.5855 | E6: =BS!E19 -> 444.9755 | F6: =BS!F19 -> 260.8922 | G6: =BS!G19 -> 362.915 | N6: =D5 -> 2021-22 | O6: =D15 -> 2.2123298 | P6: =D8 -> 72.387818 | Q6: =D22 -> 58.626523 | R6: =D29 -> 38.861424
A7: Cost of material consumed | B7: ='P&L Analysis'!B12 -> 609.3088 | C7: ='P&L Analysis'!C12 -> 726.0167 | D7: ='P&L Analysis'!D12 -> 1187.8892 | E7: ='P&L Analysis'!E12 -> 1784.1545 | F7: ='P&L Analysis'!F12 -> 1217.034 | G7: ='P&L Analysis'!G12 -> 1328.5562 | N7: =E5 -> 2022-23 | O7: =E15 -> 3.4355181 | P7: =E8 -> 91.032507 | Q7: =E22 -> 42.336283 | R7: =E29 -> 30.33475
A8: Turnover Ratio (Days) | B8: =B6/B7*365 -> 78.876421 | C8: =C6/C7*365 -> 63.435842 | D8: =D6/D7*365 -> 72.387818 | E8: =E6/E7*365 -> 91.032507 | F8: =F6/F7*365 -> 78.244037 | G8: =G6/G7*365 -> 99.70521 | N8: =F5 -> 2023-24 | O8: =F15 -> 2.2406594 | P8: =F8 -> 78.244037 | Q8: =F22 -> 53.524023 | R8: =F29 -> 33.185759
N9: =G5 -> 2024-25 | O9: =G15 -> 1.8275759 | P9: =G8 -> 99.70521 | Q9: =G22 -> 53.328461 | R9: =G29 -> 34.52141
A10: Fixed Assets T/o. Ratio
A12: Particulars | B12: =B5 -> 2019-20 | C12: =C5 -> 2020-21 | D12: =D5 -> 2021-22 | E12: =E5 -> 2022-23 | F12: =F5 -> 2023-24 | G12: =G5 -> 2024-25
A13: Fixed Assets | B13: =BS!B7 -> 215.9169 | C13: =BS!C7 -> 195.3115 | D13: =BS!D7 -> 228.7345 | E13: =BS!E7 -> 211.2394 | F13: =BS!F7 -> 262.4943 | G13: =BS!G7 -> 358.3138
A14: Sales | B14: ='P&L Analysis'!B10 -> 1038.0797 | C14: ='P&L Analysis'!C10 -> 1133.2184 | D14: ='P&L Analysis'!D10 -> 1876.2592 | E14: ='P&L Analysis'!E10 -> 3023.0766 | F14: ='P&L Analysis'!F10 -> 2122.9517 | G14: ='P&L Analysis'!G10 -> 2269.1479
A15: Turnover Ratio | C15: =C14/(C13+B13)/2 -> 1.3778455 | D15: =D14/(D13+C13)/2 -> 2.2123298 | E15: =E14/(E13+D13)/2 -> 3.4355181 | F15: =F14/(F13+E13)/2 -> 2.2406594 | G15: =G14/(G13+F13)/2 -> 1.8275759
A17: Debtor T/o. Ratio
D18: =G4 -> (no of days)
A19: Particulars | B19: =B5 -> 2019-20 | C19: =C5 -> 2020-21 | D19: =D5 -> 2021-22 | E19: =E5 -> 2022-23 | F19: =F5 -> 2023-24 | G19: =G5 -> 2024-25
A20: Debtors | B20: =BS!B21 -> 132.3332 | C20: =BS!C21 -> 161.6286 | D20: =BS!D21 -> 301.3659 | E20: =BS!E21 -> 350.6461 | F20: =BS!F21 -> 311.3121 | G20: =BS!G21 -> 331.5347
A21: Sales (Net) | B21: ='P&L Analysis'!B7 -> 1038.0797 | C21: ='P&L Analysis'!C7 -> 1133.2184 | D21: ='P&L Analysis'!D7 -> 1876.2592 | E21: ='P&L Analysis'!E7 -> 3023.0766 | F21: ='P&L Analysis'!F7 -> 2122.9517 | G21: ='P&L Analysis'!G7 -> 2269.1479
A22: Turnover Ratio (Days) | B22: =B20/B21*365 -> 46.529778 | C22: =C20/C21*365 -> 52.059196 | D22: =D20/D21*365 -> 58.626523 | E22: =E20/E21*365 -> 42.336283 | F22: =F20/F21*365 -> 53.524023 | G22: =G20/G21*365 -> 53.328461
A24: Creditors T/o. Ratio
D25: =D18 -> (no of days)
A26: Particulars | B26: =B5 -> 2019-20 | C26: =C5 -> 2020-21 | D26: =D5 -> 2021-22 | E26: =E5 -> 2022-23 | F26: =F5 -> 2023-24 | G26: =G5 -> 2024-25
A27: Creditors | B27: =BS!B43 -> 85.7508 | C27: =BS!C43 -> 97.7813 | D27: =BS!D43 -> 153.5543 | E27: =BS!E43 -> 175.8318 | F27: =BS!F43 -> 135.4094 | G27: =BS!G43 -> 155.4527
A28: Total Expense | B28: ='P&L Analysis'!B12+'P&L Analysis'!B20 -> 725.1524 | C28: ='P&L Analysis'!C12+'P&L Analysis'!C20 -> 854.3963 | D28: ='P&L Analysis'!D12+'P&L Analysis'!D20 -> 1422.4787 | E28: ='P&L Analysis'!E12+'P&L Analysis'!E20 -> 2086.6975 | F28: ='P&L Analysis'!F12+'P&L Analysis'!F20 -> 1468.9248 | G28: ='P&L Analysis'!G12+'P&L Analysis'!G20 -> 1621.1091
A29: Turnover Ratio (Days) | B29: =B27*12/B28*30 -> 42.570759 | C29: =C27*12/C28*30 -> 41.200164 | D29: =D27*12/D28*30 -> 38.861424 | E29: =E27*12/E28*30 -> 30.33475 | F29: =F27*12/F28*30 -> 33.185759 | G29: =G27*12/G28*30 -> 34.52141
A31: Debt-Equity Ratio
D32: (INR crores)
A33: Particulars | B33: =B26 -> 2019-20 | C33: =C26 -> 2020-21 | D33: =D26 -> 2021-22 | E33: =E26 -> 2022-23 | F33: =F26 -> 2023-24 | G33: =G26 -> 2024-25
A34: Debt | B34: =BS!B36+BS!B41 -> 91.4608 | C34: =BS!C36+BS!C41 -> 89.1728 | D34: =BS!D36+BS!D41 -> 58.5275 | E34: =BS!E36+BS!E41 -> 27.2041 | F34: =BS!F36+BS!F41 -> 0 | G34: =BS!G36+BS!G41 -> 0
A35: Equity | B35: =BS!B34-BS!B33 -> 618.8907 | C35: =BS!C34-BS!C33 -> 731.3867 | D35: =BS!D34-BS!D33 -> 959.2019 | E35: =BS!E34-BS!E33 -> 1541.2489 | F35: =BS!F34-BS!F33 -> 1921.0491 | G35: =BS!G34-BS!G33 -> 2295.2304
A36: Debt - Equity Ratio | B36: =B34/(B34+B35) -> 0.12875429 | C36: =C34/(C34+C35) -> 0.10867317 | D36: =D34/(D34+D35) -> 0.057507919 | E36: =E34/(E34+E35) -> 0.017344543 | F36: =F34/(F34+F35) -> 0 | G36: =G34/(G34+G35) -> 0
A38: Cost of Debt
D39: (INR crores)
A40: Particulars | B40: =B33 -> 2019-20 | C40: =C33 -> 2020-21 | D40: =D33 -> 2021-22 | E40: =E33 -> 2022-23 | F40: =F33 -> 2023-24 | G40: =G33 -> 2024-25
A41: Interest cost | B41: ='P&L Analysis'!B28 -> 4.8211 | C41: ='P&L Analysis'!C28 -> 6.1298 | D41: ='P&L Analysis'!D28 -> 4.9415 | E41: ='P&L Analysis'!E28 -> 4.5678 | F41: ='P&L Analysis'!F28 -> 2.433 | G41: ='P&L Analysis'!G28 -> 2.1956
A42: Debt | B42: =B34 -> 91.4608 | C42: =C34 -> 89.1728 | D42: =D34 -> 58.5275 | E42: =E34 -> 27.2041 | F42: =F34 -> 0 | G42: =G34 -> 0
A43: Cost of Debt (%) | B43: =B41/B42 -> 0.0527122 | C43: =C41/C42 -> 0.068740692 | D43: =D41/D42 -> 0.084430396 | E43: =E41/E42 -> 0.16790851 | F43: =IFERROR(F41/F42,0) -> 0 | G43: =IFERROR(G41/G42,0) -> 0

Sheet Forecast-->

Sheet Assumptions
A2: 1 | B2: Revenue - existing | C2: 2022-23 | D2: 2023-24 | E2: 2024-25
B3: Actual Revenue | C3: ='P&L Analysis'!E7 -> 3023.0766 | D3: ='P&L Analysis'!F7 -> 2122.9517 | E3: ='P&L Analysis'!G7 -> 2269.1479
B4: Total Output | C4: =Proj_PL!B18 -> 98170 | D4: =Proj_PL!C18 -> 99170 | E4: =Proj_PL!D18 -> 99170
B5: Price per tonne | C5: =C3*10^7/C4 -> 307943.02 | D5: =D3*10^7/D4 -> 214071.97 | E5: =E3*10^7/E4 -> 228813.95
B6: Average | C6: =AVERAGE(D5:E5) -> 221442.96
H15: Source: IMARC group
B17: As vegetable oil constitutes the primary raw material, a 7% annual price escalation has been assumed, derived from 4.62% industry CAGR and 2% inflation adjustment.
A19: 2 | B19: Revenue - JNPA SEZ
C20: 2021-22 | D20: 2022-23 | E20: 2023-24 | F20: 2024-25
B21: Fixed assets | C21: =Ratios!D13 -> 228.7345 | D21: =Ratios!E13 -> 211.2394 | E21: =Ratios!F13 -> 262.4943 | F21: =Ratios!G13 -> 358.3138
B22: Actual Revenue | D22: =Ratios!E14 -> 3023.0766 | E22: =Ratios!F14 -> 2122.9517 | F22: =Ratios!G14 -> 2269.1479
B23: Fixed assets T/o ratio | D23: =D22/(D21+C21)/2 -> 3.4355181 | E23: =E22/(E21+D21)/2 -> 2.2406594 | F23: =F22/(F21+E21)/2 -> 1.8275759
B24: Average | C24: =AVERAGE(E23:F23) -> 2.0341177
B26: JNPA SEZ investment | C26: 750 | D26: crores | E26: to be spent in stages
B27: Estimated revenue (for first 2 years) | C27: =C26*C24 -> 1525.5882 | D27: average of FY24 and FY25 being used for the first 2 years as FY24 and FY25 reflect initial operations after commissioning (Patalganga in FY22) hence the same can be used for JNPA initial years too.
A29: 2 | B29: Revenue - US Subsidiary | C29: (INR crores)
B30: Phase 1 | C30: (land of ~160 acres acquired)
B31: Initial investment | C31: 96 | D31: already infused in FY25
B32: Cash available before all capex | C32: =SUM(BS!$G$22:$G$23,BS!$G$14) -> 1168.9696 | D32: CCE and FDs with banks
B33: Cash available for US Subsidiary | C33: =C32-C26 -> 418.9696
B34: Assumption of further capex for US | C34: 400 | D34: as management plans to exhaust cash balance for capex
B35: FA T/o (conservative side) | C35: 1.2 | D35: India FA T/o assumed to be 2.03x, hence USA assumed to be on a more conservative side
B36: Estimated revenue (FY29 onwards) | C36: =(C31+C34)*C35 -> 595.2
A38: 3 | B38: Cost of Materials Consumed (net)
B39: Average net COMC of FY21 to FY25 excluding FY23 considered | C39: =ROUND(AVERAGE('P&L Analysis'!$C$14:$D$14,'P&L Analysis'!$F$14:$G$14),1) -> 0.6
A41: 4 | B41: Employee Benefit Expense
C42: 2025-26 | D42: 2026-27 | E42: 2027-28 | F42: 2028-29 | G42: 2029-30
B43: As a % to revenue | C43: 0.06 | D43: 0.065 | E43: 0.065 | F43: 0.07 | G43: 0.07 | H43: increase in EBE due to new facilities
A45: 5 | B45: Other Expenses
B46: Average other expenses of FY21 to FY25 excluding FY23 considered | C46: =AVERAGE('P&L Analysis'!$C$22:$D$22,'P&L Analysis'!$F$22:$G$22) -> 0.1214739
A48: 6 | B48: Other income
B49: Assumed constant as FY25, as all the surplus cash will be used for expansion and no further investments assumed
B50: Other income - FY25
B51: Interest income | C51: =7256.59/100 -> 72.5659 | D51: crores
B52: However, since for capex, cash amounts including FDs will be spent, the interest income accruing on the same will be affected.
A54: 7 | B54: CAPEX
D55: 2025-26 | E55: 2026-27 | F55: 2027-28 | G55: 2028-29 | H55: 2029-30
B56: Maintenance capex | D56: 30 | E56: =D56 -> 30 | F56: =E56 -> 30 | G56: =F56 -> 30 | H56: =G56 -> 30 | I56: assumed INR 30 crores
B57: Expansion capex:
B58: JNPA SEZ (750 crores in stages) | D58: =$C$26*25% -> 187.5 | E58: =$C$26*25% -> 187.5 | F58: =$C$26*20% -> 150 | G58: =$C$26*10% -> 75 | I58: assuming 20% of 750 crores spent in FY25; 25-25-20-10
...

Sheet Proj_PL
J2: (INR crores)
A3: Particulars | B3: 2022-23 | C3: 2024-25 | D3: 2024-25 | E3: 6ME Sept25 | F3: 2025-26 | G3: 2026-27 | H3: 2027-28 | I3: 2028-29 | J3: 2029-30
B4: Actuals | C4: Actuals | D4: Actuals | E4: Actuals | F4: Projected | G4: Projected | H4: Projected | I4: Projected | J4: Projected
A5: Revenue
A6: Existing Capacity (in TPA)
A7: Ambernath 1 | B7: 49500 | C7: =B7 -> 49500 | D7: =C7 -> 49500 | F7: =D7 -> 49500 | G7: =F7 -> 49500 | H7: =G7 -> 49500 | I7: =H7 -> 49500 | J7: =I7 -> 49500
A8: Ambernath 2 | B8: 5000 | C8: =B8 -> 5000 | D8: =C8 -> 5000 | F8: =D8 -> 5000 | G8: =F8 -> 5000 | H8: =G8 -> 5000 | I8: =H8 -> 5000 | J8: =I8 -> 5000
A9: Ambernath 3 | B9: 32000 | C9: =B9 -> 32000 | D9: =C9 -> 32000 | F9: =D9 -> 32000 | G9: =F9 -> 32000 | H9: =G9 -> 32000 | I9: =H9 -> 32000 | J9: =I9 -> 32000
A10: Badlapur | B10: 6400 | C10: =B10 -> 6400 | D10: =C10 -> 6400 | F10: =D10 -> 6400 | G10: =F10 -> 6400 | H10: =G10 -> 6400 | I10: =H10 -> 6400 | J10: =I10 -> 6400
A11: Dombivli | B11: 8400 | C11: =B11 -> 8400 | D11: =C11 -> 8400 | F11: =D11 -> 8400 | G11: =F11 -> 8400 | H11: =G11 -> 8400 | I11: =H11 -> 8400 | J11: =I11 -> 8400
B12: =SUM(B7:B11) -> 101300 | C12: =SUM(C7:C11) -> 101300 | D12: =SUM(D7:D11) -> 101300 | F12: =SUM(F7:F11) -> 101300 | G12: =SUM(G7:G11) -> 101300 | H12: =SUM(H7:H11) -> 101300 | I12: =SUM(I7:I11) -> 101300 | J12: =SUM(J7:J11) -> 101300
A13: Utilization | B13: 0.9 | C13: =B13 -> 0.9 | D13: =C13 -> 0.9 | F13: =D13 -> 0.9 | G13: =F13 -> 0.9 | H13: =G13 -> 0.9 | I13: =H13 -> 0.9 | J13: =I13 -> 0.9 | K13: already at full utilization; export projects shifting to JNPA SEZ in later years
A15: Patalganga (in TPA) | B15: 10000 | C15: =B15 -> 10000 | D15: =C15 -> 10000 | F15: =D15 -> 10000 | G15: =F15 -> 10000 | H15: =G15 -> 10000 | I15: =H15 -> 10000 | J15: =I15 -> 10000
A16: Utilization | B16: 0.7 | C16: 0.8 | D16: =C16 -> 0.8 | F16: 0.85 | G16: 0.9 | H16: =G16 -> 0.9 | I16: =I13 -> 0.9 | J16: =J13 -> 0.9 | K16: commissioned in FY22 and hence expected to reach full potential by FY27; export projects shifting to JNPA SEZ in later years
A18: Total output (in TPA) | B18: =(B12*B13)+(B15*B16) -> 98170 | C18: =(C12*C13)+(C15*C16) -> 99170 | D18: =(D12*D13)+(D15*D16) -> 99170 | F18: =(F12*F13)+(F15*F16) -> 99670 | G18: =(G12*G13)+(G15*G16) -> 100170 | H18: =(H12*H13)+(H15*H16) -> 100170 | I18: =(I12*I13)+(I15*I16) -> 100170 | J18: =(J12*J13)+(J15*J16) -> 100170
A19: Selling price per tonne | F19: =Assumptions!C6*1.07 -> 236943.96 | G19: =F19*1.07 -> 253530.04 | H19: =G19*1.07 -> 271277.14 | I19: =H19*1.07 -> 290266.54 | J19: =I19*1.07 -> 310585.2
A21: Revenue - existing | F21: =F18*F19/10^7 -> 2361.6205 | G21: =G18*G19/10^7 -> 2539.6104 | H21: =H18*H19/10^7 -> 2717.3831 | I21: =I18*I19/10^7 -> 2907.6 | J21: =J18*J19/10^7 -> 3111.132
A22: JNPA SEZ (est. revenue) | F22: =Assumptions!C27 -> 1525.5882 | G22: =F22 -> 1525.5882 | H22: =G22 -> 1525.5882 | I22: =H22*1.05 -> 1601.8677 | J22: =I22*1.05 -> 1681.961 | K22: 5% increment considered
A23: Utilization | F23: 0 | G23: 0 | H23: 0.45 | I23: 0.5 | J23: 0.55 | K23: (existing projects shifted) operations expected to commence FY28 onwards
A24: Revenue - JNPA SEZ | F24: =F22*F23 -> 0 | G24: =G22*G23 -> 0 | H24: =H22*H23 -> 686.51471 | I24: =I22*I23 -> 800.93383 | J24: =J22*J23 -> 925.07857
A26: US Subsidiary - Phase 1 | F26: =Assumptions!C36 -> 595.2 | G26: =F26 -> 595.2 | H26: =G26 -> 595.2 | I26: =H26 -> 595.2 | J26: =I26*1.05 -> 624.96 | K26: 5% increment considered
A27: Utilization | F27: 0 | G27: 0 | H27: 0 | I27: 0.3 | J27: 0.35 | K27: (existing US projects shifted) operations expected to commence FY29 onwards
A28: Revenue - US Subsidiary | F28: =F26*F27 -> 0 | G28: =G26*G27 -> 0 | H28: =H26*H27 -> 0 | I28: =I26*I27 -> 178.56 | J28: =J26*J27 -> 218.736
A30: Total Revenue | B30: ='P&L Analysis'!E10 -> 3023.0766 | C30: ='P&L Analysis'!F10 -> 2122.9517 | D30: ='P&L Analysis'!G10 -> 2269.1479 | E30: =118507.02/100 -> 1185.0702 | F30: =F21+F24+F28 -> 2361.6205 | G30: =G21+G24+G28 -> 2539.6104 | H30: =H21+H24+H28 -> 3403.8979 | I30: =I21+I24+I28 -> 3887.0938 | J30: =J21+J24+J28 -> 4254.9465
A31: y-o-y growth | F31: =F30/D30-1 -> 0.040752119 | G31: =G30/F30-1 -> 0.075367713 | H31: =H30/G30-1 -> 0.34032284 | I31: =I30/H30-1 -> 0.14195371 | J31: =J30/I30-1 -> 0.094634388
A33: Cost of Materials Consumed (net) | E33: =(71700.64+591.08-2336.56)/100 -> 699.5516 | F33: =Assumptions!$C$39*F30 -> 1416.9723 | G33: =Assumptions!$C$39*G30 -> 1523.7663 | H33: =Assumptions!$C$39*H30 -> 2042.3387 | I33: =Assumptions!$C$39*I30 -> 2332.2563 | J33: =Assumptions!$C$39*J30 -> 2552.9679 | K33: as a % to revenue
A34: Employee Benefit Expense | E34: =7715.72/100 -> 77.1572 | F34: =Assumptions!C43*F30 -> 141.69723 | G34: =Assumptions!D43*G30 -> 165.07468 | H34: =Assumptions!E43*H30 -> 221.25336 | I34: =Assumptions!F43*I30 -> 272.09657 | J34: =Assumptions!G43*J30 -> 297.84626 | K34: as a % to revenue
A35: Other Expenses | E35: =15021.33/100 -> 150.2133 | F35: =Assumptions!$C$46*F30 -> 286.87524 | G35: =Assumptions!$C$46*G30 -> 308.49637 | H35: =Assumptions!$C$46*H30 -> 413.48473 | I35: =Assumptions!$C$46*I30 -> 472.18042 | J35: =Assumptions!$C$46*J30 -> 516.86493 | K35: as a % to revenue
A37: EBITDA | B37: =B30-SUM(B33:B35) -> 3023.0766 | C37: =C30-SUM(C33:C35) -> 2122.9517 | D37: =D30-SUM(D33:D35) -> 2269.1479 | E37: =E30-SUM(E33:E35) -> 258.1481 | F37: =F30-SUM(F33:F35) -> 516.07573 | G37: =G30-SUM(G33:G35) -> 542.27312 | H37: =H30-SUM(H33:H35) -> 726.82105 | I37: =I30-SUM(I33:I35) -> 810.56053 | J37: =J30-SUM(J33:J35) -> 887.26743
A38: EBITDA Margins | E38: =E37/E30 -> 0.21783359 | F38: =F37/F30 -> 0.2185261 | G38: =G37/G30 -> 0.2135261 | H38: =H37/H30 -> 0.2135261 | I38: =I37/I30 -> 0.2085261 | J38: =J37/J30 -> 0.2085261
A39: Other income | E39: =6094.8/100-1565.4/100 -> 45.294 | F39: =Assumptions!C51 -> 72.5659 | G39: =F39 -> 72.5659 | H39: =G39 -> 72.5659 | I39: =H39 -> 72.5659 | J39: =I39 -> 72.5659
A40: Finance costs | F40: 0 | G40: 0 | H40: 0 | I40: 0 | J40: 0
A41: Depreciation | F41: =-(Assumptions!D67-Assumptions!C67) -> 67.35736 | G41: =-(Assumptions!E67-Assumptions!D67) -> 90.362868 | H41: =-(Assumptions!F67-Assumptions!E67) -> 108.23765 | I41: =-(Assumptions!G67-Assumptions!F67) -> 115.85098 | J41: =-(Assumptions!H67-Assumptions!G67) -> 118.4991
A42: PBT | B42: =B37+B39-B40-B41 -> 3023.0766 | C42: =C37+C39-C40-C41 -> 2122.9517 | D42: =D37+D39-D40-D41 -> 2269.1479 | E42: =E37+E39-E40-E41 -> 303.4421 | F42: =F37+F39-F40-F41 -> 521.28427 | G42: =G37+G39-G40-G41 -> 524.47615 | H42: =H37+H39-H40-H41 -> 691.1493 | I42: =I37+I39-I40-I41 -> 767.27544 | J42: =J37+J39-J40-J41 -> 841.33423
A43: PBT Margins | E43: =E42/E30 -> 0.25605411 | F43: =F42/F30 -> 0.2207316 | G43: =G42/G30 -> 0.20651835 | H43: =H42/H30 -> 0.20304643 | I43: =I42/I30 -> 0.19739051 | J43: =J42/J30 -> 0.19773086

Sheet Proj_WC
A1: WORKING CAPITAL
J2: (INR crores)
A3: Particulars | B3: 2022-23 | C3: 2024-25 | D3: 2024-25 | E3: 45930 | F3: 2025-26 | G3: 2026-27 | H3: 2027-28 | I3: 2028-29 | J3: 2029-30
B4: Actuals | C4: Actuals | D4: Actuals | E4: Actuals | F4: Projected | G4: Projected | H4: Projected | I4: Projected | J4: Projected
A6: Net working capital | B6: =WC!E26 -> 706.8506 | C6: =WC!F26 -> 466.2609 | D6: =WC!G26 -> 658.9184 | E6: =WC!H26 -> 730.1722 | F6: =F8*F9 -> 708.48615 | G6: =G8*G9 -> 761.88313 | H6: =H8*H9 -> 1021.1694 | I6: =I8*I9 -> 1166.1281 | J6: =J8*J9 -> 1276.484
A8: Revenue | B8: =Proj_PL!B30 -> 3023.0766 | C8: =Proj_PL!C30 -> 2122.9517 | D8: =Proj_PL!D30 -> 2269.1479 | E8: =Proj_PL!E30*2 -> 2370.1404 | F8: =Proj_PL!F30 -> 2361.6205 | G8: =Proj_PL!G30 -> 2539.6104 | H8: =Proj_PL!H30 -> 3403.8979 | I8: =Proj_PL!I30 -> 3887.0938 | J8: =Proj_PL!J30 -> 4254.9465
A9: % to revenue | B9: =B6/B8 -> 0.23381829 | C9: =C6/C8 -> 0.2196286 | D9: =D6/D8 -> 0.29038142 | E9: =E6/E8 -> 0.30807129 | F9: =Assumptions!C79 -> 0.3 | G9: =F9 -> 0.3 | H9: =G9 -> 0.3 | I9: =H9 -> 0.3 | J9: =I9 -> 0.3
